Workbook

Sheet Instructions
A1: UH Homes - Selections Tracker
A3: This workbook is the source of truth. You can type directly into it, or use the web app (python app.py, then open the address it prints). Both read and write these same sheets.
A5: How the workflow runs
A6: 1. Projects sheet - one row per project, with a unique Project ID such as UH-101.
A7: 2. Selections sheet - one row per product. Fill the entry columns listed below.
A8: 3. Product links - the web app finds them automatically while it is running, or run python find_urls.py (add --project UH-101 for one project, --dry-run to preview).
A9: 4. Review each link against the real product page, then set Lookup Status to Verified. Verified rows are never overwritten automatically.
A10: 5. Client Status records the client's decision: Proposed, Presented, Approved, Rejected, Changed.
A11: 6. Export the finish schedule from the web app, or run python build_lookbook.py --project UH-101 (PDF) or build_powerpoint.py (editable deck).
A13: Columns you fill in (Selections)
A14: Project ID Must match a Project ID on the Projects sheet. Dropdown.
A15: Section Category and print order; values come from the Lists sheet. Dropdown.
... A45: - Section order on the Lists sheet controls the order of categories in the client schedule.

Sheet Projects
A1: Project ID | B1: Project Name | C1: Client Name | D1: Address | E1: Plan / Elevation | F1: Designer | G1: Presentation Date | H1: Total Items | I1: Links Found | J1: Verified | K1: Needs Review | L1: Cover Image
A2: UH-101 | B2: The Magnolia Residence | C2: Example Client A | D2: 123 Example Ln, Frisco, TX | E2: Plan 2840 / Elev. B | F2: Designer Name | G2: 2026-10-01 | H2: =IF(A2="","",COUNTIF(Selections!$A:$A,A2)) | I2: =IF(A2="","",COUNTIFS(Selections!$A:$A,A2,Selections!$I:$I,"?*")) | J2: =IF(A2="","",COUNTIFS(Selections!$A:$A,A2,Selections!$L:$L,"Verified")) | K2: =IF(A2="","",H2-J2)
A3: UH-102 | B3: Cedar Ridge Custom Build | C3: Example Client B | D3: 456 Sample Dr, Prosper, TX | E3: Plan 3310 / Elev. A | F3: Designer Name | G3: 2026-10-15 | H3: =IF(A3="","",COUNTIF(Selections!$A:$A,A3)) | I3: =IF(A3="","",COUNTIFS(Selections!$A:$A,A3,Selections!$I:$I,"?*")) | J3: =IF(A3="","",COUNTIFS(Selections!$A:$A,A3,Selections!$L:$L,"Verified")) | K3: =IF(A3="","",H3-J3)
A4: UH-103 | B4: Velora | C4: Ravi Y | D4: 901 Paris Dr, Propser, TX | E4: Plan 111 / Elev. A | F4: None | G4: 46282 | H4: =IF(A4="","",COUNTIF(Selections!$A:$A,A4)) | I4: =IF(A4="","",COUNTIFS(Selections!$A:$A,A4,Selections!$I:$I,"?*")) | J4: =IF(A4="","",COUNTIFS(Selections!$A:$A,A4,Selections!$L:$L,"Verified")) | K4: =IF(A4="","",H4-J4)
H5: =IF(A5="","",COUNTIF(Selections!$A:$A,A5)) | I5: =IF(A5="","",COUNTIFS(Selections!$A:$A,A5,Selections!$I:$I,"?*")) | J5: =IF(A5="","",COUNTIFS(Selections!$A:$A,A5,Selections!$L:$L,"Verified")) | K5: =IF(A5="","",H5-J5)
H6: =IF(A6="","",COUNTIF(Selections!$A:$A,A6)) | I6: =IF(A6="","",COUNTIFS(Selections!$A:$A,A6,Selections!$I:$I,"?*")) | J6: =IF(A6="","",COUNTIFS(Selections!$A:$A,A6,Selections!$L:$L,"Verified")) | K6: =IF(A6="","",H6-J6)
H7: =IF(A7="","",COUNTIF(Selections!$A:$A,A7)) | I7: =IF(A7="","",COUNTIFS(Selections!$A:$A,A7,Selections!$I:$I,"?*")) | J7: =IF(A7="","",COUNTIFS(Selections!$A:$A,A7,Selections!$L:$L,"Verified")) | K7: =IF(A7="","",H7-J7)
H8: =IF(A8="","",COUNTIF(Selections!$A:$A,A8)) | I8: =IF(A8="","",COUNTIFS(Selections!$A:$A,A8,Selections!$I:$I,"?*")) | J8: =IF(A8="","",COUNTIFS(Selections!$A:$A,A8,Selections!$L:$L,"Verified")) | K8: =IF(A8="","",H8-J8)
H9: =IF(A9="","",COUNTIF(Selections!$A:$A,A9)) | I9: =IF(A9="","",COUNTIFS(Selections!$A:$A,A9,Selections!$I:$I,"?*")) | J9: =IF(A9="","",COUNTIFS(Selections!$A:$A,A9,Selections!$L:$L,"Verified")) | K9: =IF(A9="","",H9-J9)
H10: =IF(A10="","",COUNTIF(Selections!$A:$A,A10)) | I10: =IF(A10="","",COUNTIFS(Selections!$A:$A,A10,Selections!$I:$I,"?*")) | J10: =IF(A10="","",COUNTIFS(Selections!$A:$A,A10,Selections!$L:$L,"Verified")) | K10: =IF(A10="","",H10-J10)
H11: =IF(A11="","",COUNTIF(Selections!$A:$A,A11)) | I11: =IF(A11="","",COUNTIFS(Selections!$A:$A,A11,Selections!$I:$I,"?*")) | J11: =IF(A11="","",COUNTIFS(Selections!$A:$A,A11,Selections!$L:$L,"Verified")) | K11: =IF(A11="","",H11-J11)
H12: =IF(A12="","",COUNTIF(Selections!$A:$A,A12)) | I12: =IF(A12="","",COUNTIFS(Selections!$A:$A,A12,Selections!$I:$I,"?*")) | J12: =IF(A12="","",COUNTIFS(Selections!$A:$A,A12,Selections!$L:$L,"Verified")) | K12: =IF(A12="","",H12-J12)
H13: =IF(A13="","",COUNTIF(Selections!$A:$A,A13)) | I13: =IF(A13="","",COUNTIFS(Selections!$A:$A,A13,Selections!$I:$I,"?*")) | J13: =IF(A13="","",COUNTIFS(Selections!$A:$A,A13,Selections!$L:$L,"Verified")) | K13: =IF(A13="","",H13-J13)
H14: =IF(A14="","",COUNTIF(Selections!$A:$A,A14)) | I14: =IF(A14="","",COUNTIFS(Selections!$A:$A,A14,Selections!$I:$I,"?*")) | J14: =IF(A14="","",COUNTIFS(Selections!$A:$A,A14,Selections!$L:$L,"Verified")) | K14: =IF(A14="","",H14-J14)
H15: =IF(A15="","",COUNTIF(Selections!$A:$A,A15)) | I15: =IF(A15="","",COUNTIFS(Selections!$A:$A,A15,Selections!$I:$I,"?*")) | J15: =IF(A15="","",COUNTIFS(Selections!$A:$A,A15,Selections!$L:$L,"Verified")) | K15: =IF(A15="","",H15-J15)
H16: =IF(A16="","",COUNTIF(Selections!$A:$A,A16)) | I16: =IF(A16="","",COUNTIFS(Selections!$A:$A,A16,Selections!$I:$I,"?*")) | J16: =IF(A16="","",COUNTIFS(Selections!$A:$A,A16,Selections!$L:$L,"Verified")) | K16: =IF(A16="","",H16-J16)
... H51: =IF(A51="","",COUNTIF(Selections!$A:$A,A51)) | I51: =IF(A51="","",COUNTIFS(Selections!$A:$A,A51,Selections!$I:$I,"?*")) | J51: =IF(A51="","",COUNTIFS(Selections!$A:$A,A51,Selections!$L:$L,"Verified")) | K51: =IF(A51="","",H51-J51)

Sheet Selections
A1: Project ID | B1: Section | C1: Room / Area | D1: Item | E1: Manufacturer | F1: Model # | G1: Finish / Color | H1: Qty | I1: Product URL | J1: Product Name | K1: Image URL | L1: Lookup Status | M1: Checked On | N1: Lookup Notes | O1: Client Notes | P1: Include in Lookbook | Q1: Client Status | R1: Unit Price | S1: Markup % | T1: Description Override
A2: UH-101 | B2: Exterior | C2: Front Elevation | D2: Siding | E2: James Hardie | F2: HardiePlank Lap | G2: Arctic White | H2: 1 | L2: Not run | P2: Yes | Q2: Proposed
A3: UH-101 | B3: Windows & Doors | C3: Front Entry | D3: Entry Door | E3: Therma-Tru | F3: S4108 | G3: Black | H3: 1 | L3: Not run | P3: Yes | Q3: Proposed
A4: UH-101 | B4: Kitchen | C4: Kitchen | D4: Kitchen Faucet | E4: Moen | F4: 7594ESRS | G4: Spot Resist Stainless | H4: 1 | L4: Not run | P4: Yes | Q4: Proposed
A5: UH-101 | B5: Bathrooms | C5: Primary Bath | D5: Vanity Faucet | E5: Delta | F5: 559LF-PP | G5: Chrome | H5: 2 | L5: Not run | P5: Yes | Q5: Proposed
A6: UH-101 | B6: Paint | C6: Whole House | D6: Wall Paint | E6: Sherwin-Williams | F6: SW 7005 | G6: Pure White | L6: Not run | P6: Yes | Q6: Proposed
A7: UH-102 | B7: Kitchen | C7: Kitchen | D7: Kitchen Sink | E7: Kohler | F7: K-5540 | G7: White | H7: 1 | L7: Not run | P7: Yes | Q7: Proposed
A8: UH-102 | B8: Lighting | C8: Dining Room | D8: Chandelier | E8: Kichler | G8: Olde Bronze | H8: 1 | L8: Not run | O8: Model TBD | P8: Yes | Q8: Proposed
A9: UH-103 | B9: Windows & Doors | C9: Living Room | D9: Test 1 | E9: Dfw company | F9: xyz | G9: Black | H9: 1 | J9: Main Door | L9: Not found | M9: 2026-10-05 | N9: No page confirmed the model number. Try: https://www.google.com/search?q=Dfw+company+xyz | O9: Nothing | P9: Yes | Q9: Proposed
A10: UH-101 | B10: 1st Floor | C10: Family Room | D10: Flooring | L10: Not run | P10: Yes | Q10: Proposed
A11: UH-101 | B11: 1st Floor | C11: Family Room | D11: Fire place | L11: Not run | P11: Yes | Q11: Proposed
A12: UH-101 | B12: 1st Floor | C12: Family Room | D12: Fire place - surround | L12: Not run | P12: Yes | Q12: Proposed
A13: UH-101 | B13: 1st Floor | C13: Family Room | D13: Doors | L13: Not run | P13: Yes | Q13: Proposed
A14: UH-101 | B14: 1st Floor | C14: Family Room | D14: Light Fixture - Fan | L14: Not run | P14: Yes | Q14: Proposed
A15: UH-101 | B15: 1st Floor | C15: Family Room | D15: Wine Cellar/ Dry Bar | L15: Not run | P15: Yes | Q15: Proposed
A16: UH-101 | B16: 1st Floor | C16: Kitchen | D16: Flooring | L16: Not run | P16: Yes | Q16: Proposed
A17: UH-101 | B17: 1st Floor | C17: Kitchen | D17: Counter top | L17: Not run | P17: Yes | Q17: Proposed
A18: UH-101 | B18: 1st Floor | C18: Kitchen | D18: Backsplash | L18: Not run | P18: Yes | Q18: Proposed
A19: UH-101 | B19: 1st Floor | C19: Kitchen | D19: Coffee bar | L19: Not run | P19: Yes | Q19: Proposed
A20: UH-101 | B20: 1st Floor | C20: Kitchen | D20: Backsplash - Coffee bar | L20: Not run | P20: Yes | Q20: Proposed
A21: UH-101 | B21: 1st Floor | C21: Kitchen | D21: Venthood | L21: Not run | P21: Yes | Q21: Proposed
... A136: UH-101 | B136: 1st Floor | C136: Guest Bathroom | D136: Door Stopper | L136: Not run | P136: Yes | Q136: Proposed
A137: UH-101 | B137: 1st Floor | D137: Walls | L137: Not run | P137: Yes | Q137: Proposed
A138: UH-101 | B138: 2nd Floor | C138: Bedroom 1 | D138: Flooring | L138: Not run | P138: Yes | Q138: Proposed
A139: UH-101 | B139: 2nd Floor | C139: Bedroom 1 | D139: Light Fixture - Fan | L139: Not run | P139: Yes | Q139: Proposed
A140: UH-101 | B140: 2nd Floor | C140: Bedroom 1 | D140: Interior Door | L140: Not run | P140: Yes | Q140: Proposed
A141: UH-101 | B141: 2nd Floor | C141: Bedroom 1 | D141: Door Stopper | L141: Not run | P141: Yes | Q141: Proposed
A142: UH-101 | B142: 2nd Floor | C142: Bathroom 1 | D142: Flooring - Bath | L142: Not run | P142: Yes | Q142: Proposed
A143: UH-101 | B143: 2nd Floor | C143: Bathroom 1 | D143: Flooring - Shower Floor | L143: Not run | P143: Yes | Q143: Proposed
A144: UH-101 | B144: 2nd Floor | C144: Bathroom 1 | D144: Backsplash - Shower | L144: Not run | P144: Yes | Q144: Proposed
A145: UH-101 | B145: 2nd Floor | C145: Bathroom 1 | D145: Counter top | L145: Not run | P145: Yes | Q145: Proposed
A146: UH-101 | B146: 2nd Floor | C146: Bathroom 1 | D146: Shower Glass | L146: Not run | P146: Yes | Q146: Proposed
A147: UH-101 | B147: 2nd Floor | C147: Bathroom 1 | D147: Shower Head & Valve | L147: Not run | P147: Yes | Q147: Proposed
A148: UH-101 | B148: 2nd Floor | C148: Bathroom 1 | D148: Shower Drain | L148: Not run | P148: Yes | Q148: Proposed
A149: UH-101 | B149: 2nd Floor | C149: Bathroom 1 | D149: Vanity Mirror | L149: Not run | P149: Yes | Q149: Proposed
... A236: UH-101 | B236: 2nd Floor | C236: Media Room | D236: Door Stopper | L236: Not run | P236: Yes | Q236: Proposed
A237: UH-101 | B237: 2nd Floor | D237: Walls | L237: Not run | P237: Yes | Q237: Proposed
A238: UH-101 | B238: Outdoor Living | C238: 1st Floor - Porch (Front) | D238: Flooring | L238: Not run | P238: Yes | Q238: Proposed
A239: UH-101 | B239: Outdoor Living | C239: 1st Floor - Patio (Study) | D239: Flooring | L239: Not run | P239: Yes | Q239: Proposed
A240: UH-101 | B240: Outdoor Living | C240: 1st Floor - Patio (Family Room) | D240: Flooring | L240: Not run | P240: Yes | Q240: Proposed
...

Sheet Manufacturers
A1: Manufacturer | B1: Official Domain | C1: Notes
A2: James Hardie | B2: jameshardie.com | C2: Starter list - double-check each domain and add the brands UH Homes uses.
A3: Therma-Tru | B3: thermatru.com
A4: Pella | B4: pella.com
A5: Andersen | B5: andersenwindows.com
A6: Moen | B6: moen.com
A7: Delta | B7: deltafaucet.com
A8: Kohler | B8: kohler.com
A9: Sherwin-Williams | B9: sherwin-williams.com
A10: Behr | B10: behr.com
A11: Kichler | B11: kichler.com
A12: Daltile | B12: daltile.com
A13: Shaw | B13: shawfloors.com
A14: GE Appliances | B14: geappliances.com
... A21: Trex | B21: trex.com

Sheet Lists
A1: Sections (lookbook order) | B1: Lookup Status | C1: Yes / No | D1: Client Status
A2: Exterior | B2: Not run | C2: Yes | D2: Proposed
A3: Roofing | B3: Found - verify | C3: No | D3: Presented
A4: Windows & Doors | B4: Found - retailer | D4: Approved
A5: Kitchen | B5: Multiple matches | D5: Rejected
A6: Appliances | B6: Not found | D6: Changed
A7: Bathrooms | B7: Search error
A8: Flooring | B8: Verified
A9: Lighting
A10: Paint
A11: Interior Doors & Trim
A12: Hardware
A13: Other
A14: 1st Floor
A15: 2nd Floor
A16: Outdoor Living
A17: Garage
A18: Bulk Items

Sheet Price Schedule
A1: Price Schedule
A2: Rebuilt automatically from the Selections sheet - do not edit here. Enter costs in the Unit Price and Markup % columns on Selections; Price = Qty x Unit Price x (1 + Markup %).
A4: S.No | B4: Code | C4: Description | D4: Qty | E4: Unit Price | F4: Markup % | G4: Price
A5: UH-101 The Magnolia Residence
A6: EXTERIOR
A7: 1 | B7: EX-001 | C7: James Hardie HardiePlank Lap – Arctic White | D7: =IF(Selections!H2="",1,Selections!H2) | E7: =IF(Selections!R2="","",Selections!R2) | F7: =IF(Selections!S2="","",Selections!S2) | G7: =IF(ISNUMBER(E7),D7*E7*(1+IF(ISNUMBER(F7),F7,0)/100),"")
C8: Exterior subtotal | G8: =SUM(G7:G7)
A9: WINDOWS & DOORS
A10: 2 | B10: EX-002 | C10: Therma-Tru S4108 – Black | D10: =IF(Selections!H3="",1,Selections!H3) | E10: =IF(Selections!R3="","",Selections!R3) | F10: =IF(Selections!S3="","",Selections!S3) | G10: =IF(ISNUMBER(E10),D10*E10*(1+IF(ISNUMBER(F10),F10,0)/100),"")
C11: Windows & Doors subtotal | G11: =SUM(G10:G10)
A12: KITCHEN
A13: 3 | B13: EX-003 | C13: Moen 7594ESRS – Spot Resist Stainless | D13: =IF(Selections!H4="",1,Selections!H4) | E13: =IF(Selections!R4="","",Selections!R4) | F13: =IF(Selections!S4="","",Selections!S4) | G13: =IF(ISNUMBER(E13),D13*E13*(1+IF(ISNUMBER(F13),F13,0)/100),"")
C14: Kitchen subtotal | G14: =SUM(G13:G13)
A15: BATHROOMS
A16: 4 | B16: EX-004 | C16: Delta 559LF-PP – Chrome | D16: =IF(Selections!H5="",1,Selections!H5) | E16: =IF(Selections!R5="","",Selections!R5) | F16: =IF(Selections!S5="","",Selections!S5) | G16: =IF(ISNUMBER(E16),D16*E16*(1+IF(ISNUMBER(F16),F16,0)/100),"")
C17: Bathrooms subtotal | G17: =SUM(G16:G16)
A18: PAINT
A19: 5 | B19: EX-005 | C19: Sherwin-Williams SW 7005 – Pure White | D19: =IF(Selections!H6="",1,Selections!H6) | E19: =IF(Selections!R6="","",Selections!R6) | F19: =IF(Selections!S6="","",Selections!S6) | G19: =IF(ISNUMBER(E19),D19*E19*(1+IF(ISNUMBER(F19),F19,0)/100),"")
C20: Paint subtotal | G20: =SUM(G19:G19)
A21: 1ST FLOOR
A22: 6 | B22: EX-006 | C22: Flooring | D22: =IF(Selections!H10="",1,Selections!H10) | E22: =IF(Selections!R10="","",Selections!R10) | F22: =IF(Selections!S10="","",Selections!S10) | G22: =IF(ISNUMBER(E22),D22*E22*(1+IF(ISNUMBER(F22),F22,0)/100),"")
A23: 7 | B23: EX-007 | C23: Fire place | D23: =IF(Selections!H11="",1,Selections!H11) | E23: =IF(Selections!R11="","",Selections!R11) | F23: =IF(Selections!S11="","",Selections!S11) | G23: =IF(ISNUMBER(E23),D23*E23*(1+IF(ISNUMBER(F23),F23,0)/100),"")
A24: 8 | B24: EX-008 | C24: Fire place - surround | D24: =IF(Selections!H12="",1,Selections!H12) | E24: =IF(Selections!R12="","",Selections!R12) | F24: =IF(Selections!S12="","",Selections!S12) | G24: =IF(ISNUMBER(E24),D24*E24*(1+IF(ISNUMBER(F24),F24,0)/100),"")
A25: 9 | B25: EX-009 | C25: Doors | D25: =IF(Selections!H13="",1,Selections!H13) | E25: =IF(Selections!R13="","",Selections!R13) | F25: =IF(Selections!S13="","",Selections!S13) | G25: =IF(ISNUMBER(E25),D25*E25*(1+IF(ISNUMBER(F25),F25,0)/100),"")
A26: 10 | B26: EX-010 | C26: Light Fixture - Fan | D26: =IF(Selections!H14="",1,Selections!H14) | E26: =IF(Selections!R14="","",Selections!R14) | F26: =IF(Selections!S14="","",Selections!S14) | G26: =IF(ISNUMBER(E26),D26*E26*(1+IF(ISNUMBER(F26),F26,0)/100),"")
A27: 11 | B27: EX-011 | C27: Wine Cellar/ Dry Bar | D27: =IF(Selections!H15="",1,Selections!H15) | E27: =IF(Selections!R15="","",Selections!R15) | F27: =IF(Selections!S15="","",Selections!S15) | G27: =IF(ISNUMBER(E27),D27*E27*(1+IF(ISNUMBER(F27),F27,0)/100),"")
A28: 12 | B28: EX-012 | C28: Flooring | D28: =IF(Selections!H16="",1,Selections!H16) | E28: =IF(Selections!R16="","",Selections!R16) | F28: =IF(Selections!S16="","",Selections!S16) | G28: =IF(ISNUMBER(E28),D28*E28*(1+IF(ISNUMBER(F28),F28,0)/100),"")
A29: 13 | B29: EX-013 | C29: Counter top | D29: =IF(Selections!H17="",1,Selections!H17) | E29: =IF(Selections!R17="","",Selections!R17) | F29: =IF(Selections!S17="","",Selections!S17) | G29: =IF(ISNUMBER(E29),D29*E29*(1+IF(ISNUMBER(F29),F29,0)/100),"")
A30: 14 | B30: EX-014 | C30: Backsplash | D30: =IF(Selections!H18="",1,Selections!H18) | E30: =IF(Selections!R18="","",Selections!R18) | F30: =IF(Selections!S18="","",Selections!S18) | G30: =IF(ISNUMBER(E30),D30*E30*(1+IF(ISNUMBER(F30),F30,0)/100),"")
A31: 15 | B31: EX-015 | C31: Coffee bar | D31: =IF(Selections!H19="",1,Selections!H19) | E31: =IF(Selections!R19="","",Selections!R19) | F31: =IF(Selections!S19="","",Selections!S19) | G31: =IF(ISNUMBER(E31),D31*E31*(1+IF(ISNUMBER(F31),F31,0)/100),"")
A32: 16 | B32: EX-016 | C32: Backsplash - Coffee bar | D32: =IF(Selections!H20="",1,Selections!H20) | E32: =IF(Selections!R20="","",Selections!R20) | F32: =IF(Selections!S20="","",Selections!S20) | G32: =IF(ISNUMBER(E32),D32*E32*(1+IF(ISNUMBER(F32),F32,0)/100),"")
A33: 17 | B33: EX-017 | C33: Venthood | D33: =IF(Selections!H21="",1,Selections!H21) | E33: =IF(Selections!R21="","",Selections!R21) | F33: =IF(Selections!S21="","",Selections!S21) | G33: =IF(ISNUMBER(E33),D33*E33*(1+IF(ISNUMBER(F33),F33,0)/100),"")
... A149: 133 | B149: EX-133 | C149: Walls | D149: =IF(Selections!H137="",1,Selections!H137) | E149: =IF(Selections!R137="","",Selections!R137) | F149: =IF(Selections!S137="","",Selections!S137) | G149: =IF(ISNUMBER(E149),D149*E149*(1+IF(ISNUMBER(F149),F149,0)/100),"")
C150: 1st Floor subtotal | G150: =SUM(G22:G149)
A151: 2ND FLOOR
A152: 134 | B152: EX-134 | C152: Flooring | D152: =IF(Selections!H138="",1,Selections!H138) | E152: =IF(Selections!R138="","",Selections!R138) | F152: =IF(Selections!S138="","",Selections!S138) | G152: =IF(ISNUMBER(E152),D152*E152*(1+IF(ISNUMBER(F152),F152,0)/100),"")
A153: 135 | B153: EX-135 | C153: Light Fixture - Fan | D153: =IF(Selections!H139="",1,Selections!H139) | E153: =IF(Selections!R139="","",Selections!R139) | F153: =IF(Selections!S139="","",Selections!S139) | G153: =IF(ISNUMBER(E153),D153*E153*(1+IF(ISNUMBER(F153),F153,0)/100),"")
A154: 136 | B154: EX-136 | C154: Interior Door | D154: =IF(Selections!H140="",1,Selections!H140) | E154: =IF(Selections!R140="","",Selections!R140) | F154: =IF(Selections!S140="","",Selections!S140) | G154: =IF(ISNUMBER(E154),D154*E154*(1+IF(ISNUMBER(F154),F154,0)/100),"")
A155: 137 | B155: EX-137 | C155: Door Stopper | D155: =IF(Selections!H141="",1,Selections!H141) | E155: =IF(Selections!R141="","",Selections!R141) | F155: =IF(Selections!S141="","",Selections!S141) | G155: =IF(ISNUMBER(E155),D155*E155*(1+IF(ISNUMBER(F155),F155,0)/100),"")
A156: 138 | B156: EX-138 | C156: Flooring - Bath | D156: =IF(Selections!H142="",1,Selections!H142) | E156: =IF(Selections!R142="","",Selections!R142) | F156: =IF(Selections!S142="","",Selections!S142) | G156: =IF(ISNUMBER(E156),D156*E156*(1+IF(ISNUMBER(F156),F156,0)/100),"")
...
